<sdf version='1.7'>
  <world name='conveyor'>
    <gravity>0 0 -9.8</gravity>
    <model name='ground_plane'>
      <static>1</static>
      <link name='link'>
        <collision name='collision'>
          <geometry>
            <plane>
              <normal>0 0 1</normal>
              <size>100 100</size>
            </plane>
          </geometry>
          <surface>
            <friction>
              <ode>
                <mu>100</mu>
                <mu2>50</mu2>
              </ode>
              <torsional>
                <ode/>
              </torsional>
            </friction>
            <contact>
              <ode/>
            </contact>
            <bounce/>
          </surface>
          <max_contacts>10</max_contacts>
        </collision>
        <visual name='visual'>
          <cast_shadows>0</cast_shadows>
          <geometry>
            <plane>
              <normal>0 0 1</normal>
              <size>100 100</size>
            </plane>
          </geometry>
          <material>
            <script>
              <uri>file://media/materials/scripts/gazebo.material</uri>
              <name>Gazebo/Grey</name>
            </script>
          </material>
        </visual>
        <self_collide>0</self_collide>
        <enable_wind>0</enable_wind>
        <kinematic>0</kinematic>
      </link>
    </model>
    <light name='sun' type='directional'>
      <cast_shadows>1</cast_shadows>
      <pose>0 0 10 0 -0 0</pose>
      <diffuse>0.8 0.8 0.8 1</diffuse>
      <specular>0.2 0.2 0.2 1</specular>
      <attenuation>
        <range>1000</range>
        <constant>0.9</constant>
        <linear>0.01</linear>
        <quadratic>0.001</quadratic>
      </attenuation>
      <direction>-0.5 0.1 -0.9</direction>
      <spot>
        <inner_angle>0</inner_angle>
        <outer_angle>0</outer_angle>
        <falloff>0</falloff>
      </spot>
    </light>
    <scene>
      <shadows>0</shadows>
      <ambient>0.4 0.4 0.4 1</ambient>
      <background>0.7 0.7 0.7 1</background>
    </scene>
    <model name='conveyor_belt'>
      <model name='conveyorbelt_fixed_1'>
        <static>1</static>
        <link name='belt_visual_1'>
          <pose>7.1 -2.8 0 0 -0 1.57</pose>
          <visual name='visual'>
            <geometry>
              <mesh>
                <scale>1 0.8 0.4</scale>
                <uri>model://conveyor_belt/meshes/conveyor_belt.dae</uri>
              </mesh>
            </geometry>
          </visual>
          <collision name='collision_1'>
            <geometry>
              <mesh>
                <scale>1 0.8 0.4</scale>
                <uri>model://conveyor_belt/meshes/conveyor_belt.dae</uri>
              </mesh>
            </geometry>
            <max_contacts>10</max_contacts>
            <surface>
              <contact>
                <ode/>
              </contact>
              <bounce/>
              <friction>
                <torsional>
                  <ode/>
                </torsional>
                <ode/>
              </friction>
            </surface>
            <origin xyz='7.1 -2.8 0' rpy='0.0 0.0 1.57'/>
          </collision>
          <self_collide>0</self_collide>
          <enable_wind>0</enable_wind>
          <kinematic>0</kinematic>
        </link>
      </model>
      <model name='conveyorbelt_moving_1'>
        <allow_auto_disable>0</allow_auto_disable>
        <static>0</static>
        <pose>7.1 -2.8 0.3 0 -0 1.57</pose>
        <link name='belt_moving_1'>
          <inertial>
            <mass>100</mass>
            <inertia>
              <ixx>0</ixx>
              <ixy>0</ixy>
              <ixz>0</ixz>
              <iyy>0</iyy>
              <iyz>0</iyz>
              <izz>0</izz>
            </inertia>
            <pose>7.1 -2.8 0.3 0 -0 1.57</pose>
          </inertial>
          <collision name='belt_collision_1'>
            <geometry>
              <box>
                <size>0.425 0.95 1e-05</size>
              </box>
            </geometry>
            <surface>
              <friction>
                <ode>
                  <mu>100</mu>
                  <mu2>100</mu2>
                </ode>
                <torsional>
                  <coefficient>1000</coefficient>
                  <patch_radius>0.1</patch_radius>
                  <ode/>
                </torsional>
              </friction>
              <contact>
                <ode/>
              </contact>
              <bounce/>
            </surface>
            <max_contacts>10</max_contacts>
          </collision>
          <self_collide>0</self_collide>
          <enable_wind>0</enable_wind>
          <kinematic>0</kinematic>
        </link>
      </model>
      <model name='conveyorbelt_fixed_2'>
        <static>1</static>
        <link name='belt_visual_2'>
          <pose>10.6 -2.8 0 0 -0 1.57</pose>
          <visual name='visual'>
            <geometry>
              <mesh>
                <scale>1 0.8 0.4</scale>
                <uri>model://conveyor_belt/meshes/conveyor_belt.dae</uri>
              </mesh>
            </geometry>
          </visual>
          <collision name='collision_2'>
            <geometry>
              <mesh>
                <scale>1 0.8 0.4</scale>
                <uri>model://conveyor_belt/meshes/conveyor_belt.dae</uri>
              </mesh>
            </geometry>
            <max_contacts>10</max_contacts>
            <surface>
              <contact>
                <ode/>
              </contact>
              <bounce/>
              <friction>
                <torsional>
                  <ode/>
                </torsional>
                <ode/>
              </friction>
            </surface>
            <origin xyz='10.6 -2.8 0' rpy='0.0 0.0 1.57'/>
          </collision>
          <self_collide>0</self_collide>
          <enable_wind>0</enable_wind>
          <kinematic>0</kinematic>
        </link>
      </model>
      <model name='conveyorbelt_moving_2'>
        <allow_auto_disable>0</allow_auto_disable>
        <static>0</static>
        <pose>10.6 -2.8 0.3 0 -0 1.57</pose>
        <link name='belt_moving_2'>
          <inertial>
            <mass>100</mass>
            <inertia>
              <ixx>0</ixx>
              <ixy>0</ixy>
              <ixz>0</ixz>
              <iyy>0</iyy>
              <iyz>0</iyz>
              <izz>0</izz>
            </inertia>
            <pose>0 0 0 0 -0 0</pose>
          </inertial>
          <collision name='belt_collision_2'>
            <geometry>
              <box>
                <size>0.425 0.95 1e-05</size>
              </box>
            </geometry>
            <surface>
              <friction>
                <ode>
                  <mu>100</mu>
                  <mu2>100</mu2>
                </ode>
                <torsional>
                  <coefficient>1000</coefficient>
                  <patch_radius>0.1</patch_radius>
                  <ode/>
                </torsional>
              </friction>
              <contact>
                <ode/>
              </contact>
              <bounce/>
            </surface>
            <max_contacts>10</max_contacts>
          </collision>
          <self_collide>0</self_collide>
          <enable_wind>0</enable_wind>
          <kinematic>0</kinematic>
        </link>
      </model>
      <model name='conveyorbelt_fixed_3'>
        <static>1</static>
        <link name='belt_visual_3'>
          <pose>12.6 -2.8 0 0 -0 1.57</pose>
          <visual name='visual'>
            <geometry>
              <mesh>
                <scale>1 0.8 0.4</scale>
                <uri>model://conveyor_belt/meshes/conveyor_belt.dae</uri>
              </mesh>
            </geometry>
          </visual>
          <collision name='collision_3'>
            <geometry>
              <mesh>
                <scale>1 0.8 0.4</scale>
                <uri>model://conveyor_belt/meshes/conveyor_belt.dae</uri>
              </mesh>
            </geometry>
            <max_contacts>10</max_contacts>
            <surface>
              <contact>
                <ode/>
              </contact>
              <bounce/>
              <friction>
                <torsional>
                  <ode/>
                </torsional>
                <ode/>
              </friction>
            </surface>
            <origin xyz='12.6 -2.8 0' rpy='0.0 0.0 1.57'/>
          </collision>
          <self_collide>0</self_collide>
          <enable_wind>0</enable_wind>
          <kinematic>0</kinematic>
        </link>
      </model>
      <model name='conveyorbelt_moving_3'>
        <allow_auto_disable>0</allow_auto_disable>
        <static>0</static>
        <pose>12.6 -2.8 0.3 0 -0 1.57</pose>
        <link name='belt_moving_3'>
          <inertial>
            <mass>100</mass>
            <inertia>
              <ixx>0</ixx>
              <ixy>0</ixy>
              <ixz>0</ixz>
              <iyy>0</iyy>
              <iyz>0</iyz>
              <izz>0</izz>
            </inertia>
            <pose>0 0 0 0 -0 0</pose>
          </inertial>
          <collision name='belt_collision_3'>
            <geometry>
              <box>
                <size>0.425 0.95 1e-05</size>
              </box>
            </geometry>
            <surface>
              <friction>
                <ode>
                  <mu>100</mu>
                  <mu2>100</mu2>
                </ode>
                <torsional>
                  <coefficient>1000</coefficient>
                  <patch_radius>0.1</patch_radius>
                  <ode/>
                </torsional>
              </friction>
              <contact>
                <ode/>
              </contact>
              <bounce/>
            </surface>
            <max_contacts>10</max_contacts>
          </collision>
          <self_collide>0</self_collide>
          <enable_wind>0</enable_wind>
          <kinematic>0</kinematic>
        </link>
      </model>
      <joint name='belt_joint_1' type='prismatic'>
        <parent>conveyorbelt_fixed_1::belt_visual_1</parent>
        <child>conveyorbelt_moving_1::belt_moving_1</child>
        <axis>
          <xyz expressed_in='__model__'>-1 0 0</xyz>
          <limit>
            <lower>0</lower>
            <upper>0.01</upper>
          </limit>
          <dynamics>
            <spring_reference>0</spring_reference>
            <spring_stiffness>0</spring_stiffness>
          </dynamics>
        </axis>
      </joint>
      <joint name='belt_joint_2' type='prismatic'>
        <parent>conveyorbelt_fixed_2::belt_visual_2</parent>
        <child>conveyorbelt_moving_2::belt_moving_2</child>
        <axis>
          <xyz expressed_in='__model__'>-1 0 0</xyz>
          <limit>
            <lower>0</lower>
            <upper>0.01</upper>
          </limit>
          <dynamics>
            <spring_reference>0</spring_reference>
            <spring_stiffness>0</spring_stiffness>
          </dynamics>
        </axis>
      </joint>
      <joint name='belt_joint_3' type='prismatic'>
        <parent>conveyorbelt_fixed_3::belt_visual_3</parent>
        <child>conveyorbelt_moving_3::belt_moving_3</child>
        <axis>
          <xyz expressed_in='__model__'>-1 0 0</xyz>
          <limit>
            <lower>0</lower>
            <upper>0.01</upper>
          </limit>
          <dynamics>
            <spring_reference>0</spring_reference>
            <spring_stiffness>0</spring_stiffness>
          </dynamics>
        </axis>
      </joint>
      <plugin name='ros2_conveyorbelt_plugin' filename='libros2_conveyorbelt_plugin.so'>
        <ros>
          <namespace/>
        </ros>
        <belt_changer_velocity>0.3</belt_changer_velocity>
        <max_velocity_1>1.0</max_velocity_1>
        <max_velocity_2>1.0</max_velocity_2>
        <max_velocity_3>1.0</max_velocity_3>
        <publish_rate>1000</publish_rate>
      </plugin>
    </model>
    <magnetic_field>6e-06 2.3e-05 -4.2e-05</magnetic_field>
    <atmosphere type='adiabatic'/>
    <physics type='ode'>
      <max_step_size>0.001</max_step_size>
      <real_time_factor>1</real_time_factor>
      <real_time_update_rate>1000</real_time_update_rate>
    </physics>
    <audio>
      <device>default</device>
    </audio>
    <wind/>
    <spherical_coordinates>
      <surface_model>EARTH_WGS84</surface_model>
      <latitude_deg>0</latitude_deg>
      <longitude_deg>0</longitude_deg>
      <elevation>0</elevation>
      <heading_deg>0</heading_deg>
    </spherical_coordinates>
    <model name='unit_box'>
      <link name='link'>
        <inertial>
          <mass>1</mass>
          <inertia>
            <ixx>0.000166667</ixx>
            <ixy>0</ixy>
            <ixz>0</ixz>
            <iyy>0.000166667</iyy>
            <iyz>0</iyz>
            <izz>0.000166667</izz>
          </inertia>
          <pose>0 0 0 0 -0 0</pose>
        </inertial>
        <self_collide>0</self_collide>
        <enable_wind>0</enable_wind>
        <kinematic>0</kinematic>
        <pose>0 0 0 0 -0 0</pose>
        <gravity>1</gravity>
        <visual name='visual'>
          <geometry>
            <box>
              <size>0.1 0.1 0.1</size>
            </box>
          </geometry>
          <material>
            <script>
              <name>Gazebo/Grey</name>
              <uri>file://media/materials/scripts/gazebo.material</uri>
            </script>
            <shader type='pixel'>
              <normal_map>__default__</normal_map>
            </shader>
            <ambient>0.3 0.3 0.3 1</ambient>
            <diffuse>0.7 0.7 0.7 1</diffuse>
            <specular>0.01 0.01 0.01 1</specular>
            <emissive>0 0 0 1</emissive>
          </material>
          <pose>0 0 0 0 -0 0</pose>
          <transparency>0</transparency>
          <cast_shadows>1</cast_shadows>
        </visual>
        <collision name='collision'>
          <laser_retro>0</laser_retro>
          <max_contacts>0</max_contacts>
          <pose>0 0 0 0 -0 0</pose>
          <geometry>
            <box>
              <size>0.1 0.1 0.08</size>
            </box>
          </geometry>
          <surface>
            <friction>
              <ode>
                <mu>1</mu>
                <mu2>1</mu2>
                <fdir1>0 0 0</fdir1>
                <slip1>0</slip1>
                <slip2>0</slip2>
              </ode>
              <torsional>
                <coefficient>1</coefficient>
                <patch_radius>0</patch_radius>
                <surface_radius>0</surface_radius>
                <use_patch_radius>1</use_patch_radius>
                <ode>
                  <slip>0</slip>
                </ode>
              </torsional>
            </friction>
            <bounce>
              <restitution_coefficient>0</restitution_coefficient>
              <threshold>1e+06</threshold>
            </bounce>
            <contact>
              <collide_without_contact>0</collide_without_contact>
              <collide_without_contact_bitmask>1</collide_without_contact_bitmask>
              <collide_bitmask>1</collide_bitmask>
              <ode>
                <soft_cfm>0</soft_cfm>
                <soft_erp>0.2</soft_erp>
                <kp>1e+13</kp>
                <kd>1</kd>
                <max_vel>0.01</max_vel>
                <min_depth>0</min_depth>
              </ode>
              <bullet>
                <split_impulse>1</split_impulse>
                <split_impulse_penetration_threshold>-0.01</split_impulse_penetration_threshold>
                <soft_cfm>0</soft_cfm>
                <soft_erp>0.2</soft_erp>
                <kp>1e+13</kp>
                <kd>1</kd>
              </bullet>
            </contact>
          </surface>
        </collision>
      </link>
      <static>0</static>
      <allow_auto_disable>1</allow_auto_disable>
      <pose>-0.48043 0.125688 0 0 -0 0</pose>
    </model>
    <state world_name='default'>
      <sim_time>325 378000000</sim_time>
      <real_time>44 288156662</real_time>
      <wall_time>1740278476 690991735</wall_time>
      <iterations>43896</iterations>
      <model name='conveyor_belt'>
        <pose>-0 0 0 0 -0 0</pose>
        <scale>1 1 1</scale>
        <model name='conveyorbelt_fixed_1'>
          <pose>-0 0 0 0 -0 0</pose>
          <scale>1 1 1</scale>
          <link name='belt_visual_1'>
            <pose>7.1 -2.8 0 0 -0 1.57</pose>
            <velocity>0 0 0 0 -0 0</velocity>
            <acceleration>0 0 0 0 -0 0</acceleration>
            <wrench>0 0 0 0 -0 0</wrench>
          </link>
        </model>
        <model name='conveyorbelt_fixed_2'>
          <pose>0 0 0 0 -0 0</pose>
          <scale>1 1 1</scale>
          <link name='belt_visual_2'>
            <pose>10.6 -2.8 0 0 -0 1.57</pose>
            <velocity>0 0 0 0 -0 0</velocity>
            <acceleration>0 0 0 0 -0 0</acceleration>
            <wrench>0 0 0 0 -0 0</wrench>
          </link>
        </model>
        <model name='conveyorbelt_fixed_3'>
          <pose>0 0 0 0 -0 0</pose>
          <scale>1 1 1</scale>
          <link name='belt_visual_3'>
            <pose>12.6 -2.8 0 0 -0 1.57</pose>
            <velocity>0 0 0 0 -0 0</velocity>
            <acceleration>0 0 0 0 -0 0</acceleration>
            <wrench>0 0 0 0 -0 0</wrench>
          </link>
        </model>
        <model name='conveyorbelt_moving_1'>
          <pose>0 0 0.3 0 -0 0</pose>
          <scale>1 1 1</scale>
          <link name='belt_moving_1'>
            <pose>7.09927 -2.8 0.299981 -1e-06 -2e-06 1.57</pose>
            <velocity>0.001219 -0.000284 -0.004659 0.000576 -0.000204 0.000163</velocity>
            <acceleration>0.001411 3.8e-05 -0.000792 0 -0 0</acceleration>
            <wrench>0.141093 0.003828 -0.079161 0 -0 0</wrench>
          </link>
        </model>
        <model name='conveyorbelt_moving_2'>
          <pose>0 0 0.3 0 -0 0</pose>
          <scale>1 1 1</scale>
          <link name='belt_moving_2'>
            <pose>10.5913 -2.8 0.3 0 -0 1.57</pose>
            <velocity>-6.1e-05 -1e-06 0 1e-06 -3e-06 -1.5e-05</velocity>
            <acceleration>-0.060731 -0.000578 7.8e-05 0 -0 0</acceleration>
            <wrench>-6.07308 -0.057848 0.007841 0 -0 0</wrench>
          </link>
        </model>
        <model name='conveyorbelt_moving_3'>
          <pose>0 0 0.3 0 -0 0</pose>
          <scale>1 1 1</scale>
          <link name='belt_moving_3'>
            <pose>12.5997 -2.8 0.3 0 -0 1.57</pose>
            <velocity>-8e-06 0 -0 0 1e-06 1e-06</velocity>
            <acceleration>-0.007945 4.9e-05 -1.7e-05 0 -0 0</acceleration>
            <wrench>-0.794478 0.004927 -0.001717 0 -0 0</wrench>
          </link>
        </model>
      </model>
      <model name='ground_plane'>
        <pose>0 0 0 0 -0 0</pose>
        <scale>1 1 1</scale>
        <link name='link'>
          <pose>0 0 0 0 -0 0</pose>
          <velocity>0 0 0 0 -0 0</velocity>
          <acceleration>0 0 0 0 -0 0</acceleration>
          <wrench>0 0 0 0 -0 0</wrench>
        </link>
      </model>
      <model name='unit_box'>
        <pose>7.48202 -2.79231 0.33999 3.14156 5.8e-05 -0.220071</pose>
        <scale>1 1 1</scale>
        <link name='link'>
          <pose>7.48202 -2.79231 0.33999 3.14156 5.8e-05 -0.220071</pose>
          <velocity>0.001602 0.000487 0.006438 -0.01709 0.008632 0.000224</velocity>
          <acceleration>-0.141672 0.434143 13.7712 -1.40175 -0.565914 0.277558</acceleration>
          <wrench>-0.141672 0.434143 13.7712 0 -0 0</wrench>
        </link>
      </model>
      <model name='unit_box_clone'>
        <pose>10.8638 -2.7929 0.340005 1e-05 -3e-05 0.035774</pose>
        <scale>1 1 1</scale>
        <link name='link'>
          <pose>10.8638 -2.7929 0.340005 1e-05 -3e-05 0.035774</pose>
          <velocity>0.002746 -0.000336 0.005351 0.008012 0.070354 -4.4e-05</velocity>
          <acceleration>6.07307 -0.280468 10.6458 3.13548 -0.773594 -3.11547</acceleration>
          <wrench>6.07307 -0.280468 10.6458 0 -0 0</wrench>
        </link>
      </model>
      <model name='unit_box_clone_clone'>
        <pose>12.8319 -2.79898 0.340001 3.14159 8.8e-05 0.085648</pose>
        <scale>1 1 1</scale>
        <link name='link'>
          <pose>12.8319 -2.79898 0.340001 3.14159 8.8e-05 0.085648</pose>
          <velocity>0.002963 0.000237 -0.004664 -0.004021 0.112925 0.00036</velocity>
          <acceleration>0.794475 -0.371943 -9.00553 -1.69475 0.582741 0.320492</acceleration>
          <wrench>0.794475 -0.371943 -9.00553 0 -0 0</wrench>
        </link>
      </model>
      <light name='sun'>
        <pose>0 0 10 0 -0 0</pose>
      </light>
    </state>
    <gui fullscreen='0'>
      <camera name='user_camera'>
        <pose>12.3553 -10.4229 1.36423 0 0.058938 1.69304</pose>
        <view_controller>orbit</view_controller>
        <projection_type>perspective</projection_type>
      </camera>
    </gui>
    <model name='unit_box_clone'>
      <link name='link'>
        <inertial>
          <mass>1</mass>
          <inertia>
            <ixx>0.000166667</ixx>
            <ixy>0</ixy>
            <ixz>0</ixz>
            <iyy>0.000166667</iyy>
            <iyz>0</iyz>
            <izz>0.000166667</izz>
          </inertia>
          <pose>0 0 0 0 -0 0</pose>
        </inertial>
        <self_collide>0</self_collide>
        <enable_wind>0</enable_wind>
        <kinematic>0</kinematic>
        <pose>0 0 0 0 -0 0</pose>
        <gravity>1</gravity>
        <visual name='visual'>
          <geometry>
            <box>
              <size>0.1 0.1 0.1</size>
            </box>
          </geometry>
          <material>
            <script>
              <name>Gazebo/Grey</name>
              <uri>file://media/materials/scripts/gazebo.material</uri>
            </script>
            <shader type='pixel'>
              <normal_map>__default__</normal_map>
            </shader>
            <ambient>0.3 0.3 0.3 1</ambient>
            <diffuse>0.7 0.7 0.7 1</diffuse>
            <specular>0.01 0.01 0.01 1</specular>
            <emissive>0 0 0 1</emissive>
          </material>
          <pose>0 0 0 0 -0 0</pose>
          <transparency>0</transparency>
          <cast_shadows>1</cast_shadows>
        </visual>
        <collision name='collision'>
          <laser_retro>0</laser_retro>
          <max_contacts>0</max_contacts>
          <pose>0 0 0 0 -0 0</pose>
          <geometry>
            <box>
              <size>0.1 0.1 0.08</size>
            </box>
          </geometry>
          <surface>
            <friction>
              <ode>
                <mu>1</mu>
                <mu2>1</mu2>
                <fdir1>0 0 0</fdir1>
                <slip1>0</slip1>
                <slip2>0</slip2>
              </ode>
              <torsional>
                <coefficient>1</coefficient>
                <patch_radius>0</patch_radius>
                <surface_radius>0</surface_radius>
                <use_patch_radius>1</use_patch_radius>
                <ode>
                  <slip>0</slip>
                </ode>
              </torsional>
            </friction>
            <bounce>
              <restitution_coefficient>0</restitution_coefficient>
              <threshold>1e+06</threshold>
            </bounce>
            <contact>
              <collide_without_contact>0</collide_without_contact>
              <collide_without_contact_bitmask>1</collide_without_contact_bitmask>
              <collide_bitmask>1</collide_bitmask>
              <ode>
                <soft_cfm>0</soft_cfm>
                <soft_erp>0.2</soft_erp>
                <kp>1e+13</kp>
                <kd>1</kd>
                <max_vel>0.01</max_vel>
                <min_depth>0</min_depth>
              </ode>
              <bullet>
                <split_impulse>1</split_impulse>
                <split_impulse_penetration_threshold>-0.01</split_impulse_penetration_threshold>
                <soft_cfm>0</soft_cfm>
                <soft_erp>0.2</soft_erp>
                <kp>1e+13</kp>
                <kd>1</kd>
              </bullet>
            </contact>
          </surface>
        </collision>
      </link>
      <static>0</static>
      <allow_auto_disable>1</allow_auto_disable>
      <pose>0.997593 -1.88065 0.340012 -3e-06 3.1e-05 0.002374</pose>
    </model>
    <model name='unit_box_clone_clone'>
      <link name='link'>
        <inertial>
          <mass>1</mass>
          <inertia>
            <ixx>0.000166667</ixx>
            <ixy>0</ixy>
            <ixz>0</ixz>
            <iyy>0.000166667</iyy>
            <iyz>0</iyz>
            <izz>0.000166667</izz>
          </inertia>
          <pose>0 0 0 0 -0 0</pose>
        </inertial>
        <self_collide>0</self_collide>
        <enable_wind>0</enable_wind>
        <kinematic>0</kinematic>
        <pose>0 0 0 0 -0 0</pose>
        <gravity>1</gravity>
        <visual name='visual'>
          <geometry>
            <box>
              <size>0.1 0.1 0.1</size>
            </box>
          </geometry>
          <material>
            <script>
              <name>Gazebo/Grey</name>
              <uri>file://media/materials/scripts/gazebo.material</uri>
            </script>
            <shader type='pixel'>
              <normal_map>__default__</normal_map>
            </shader>
            <ambient>0.3 0.3 0.3 1</ambient>
            <diffuse>0.7 0.7 0.7 1</diffuse>
            <specular>0.01 0.01 0.01 1</specular>
            <emissive>0 0 0 1</emissive>
          </material>
          <pose>0 0 0 0 -0 0</pose>
          <transparency>0</transparency>
          <cast_shadows>1</cast_shadows>
        </visual>
        <collision name='collision'>
          <laser_retro>0</laser_retro>
          <max_contacts>0</max_contacts>
          <pose>0 0 0 0 -0 0</pose>
          <geometry>
            <box>
              <size>0.1 0.1 0.08</size>
            </box>
          </geometry>
          <surface>
            <friction>
              <ode>
                <mu>1</mu>
                <mu2>1</mu2>
                <fdir1>0 0 0</fdir1>
                <slip1>0</slip1>
                <slip2>0</slip2>
              </ode>
              <torsional>
                <coefficient>1</coefficient>
                <patch_radius>0</patch_radius>
                <surface_radius>0</surface_radius>
                <use_patch_radius>1</use_patch_radius>
                <ode>
                  <slip>0</slip>
                </ode>
              </torsional>
            </friction>
            <bounce>
              <restitution_coefficient>0</restitution_coefficient>
              <threshold>1e+06</threshold>
            </bounce>
            <contact>
              <collide_without_contact>0</collide_without_contact>
              <collide_without_contact_bitmask>1</collide_without_contact_bitmask>
              <collide_bitmask>1</collide_bitmask>
              <ode>
                <soft_cfm>0</soft_cfm>
                <soft_erp>0.2</soft_erp>
                <kp>1e+13</kp>
                <kd>1</kd>
                <max_vel>0.01</max_vel>
                <min_depth>0</min_depth>
              </ode>
              <bullet>
                <split_impulse>1</split_impulse>
                <split_impulse_penetration_threshold>-0.01</split_impulse_penetration_threshold>
                <soft_cfm>0</soft_cfm>
                <soft_erp>0.2</soft_erp>
                <kp>1e+13</kp>
                <kd>1</kd>
              </bullet>
            </contact>
          </surface>
        </collision>
      </link>
      <static>0</static>
      <allow_auto_disable>1</allow_auto_disable>
      <pose>11.9475 -3.04824 0.336 -1.1e-05 1e-06 -0.004616</pose>
    </model>
  </world>
</sdf>
